Workbook

Sheet Final
A1: T | B1: TK | C1: VOLM m3 | D1: DISP | E1: LCA | F1: CB | G1: LCB | H1: VCB | I1: XMT | J1: XML
A2: 2 | B2: 2.021 | C2: 6979.7 | D2: 7234.4 | E2: 108.555 | F2: 0.4708 | G2: 108365 | H2: 1.062 | I2: 37.178 | J2: 1043.77
A3: 2.1 | B3: 2.121 | C3: 7388.9 | D3: 7655 | E3: 108.558 | F3: 0.4747 | G3: 54236.691 | H3: 1.116 | I3: 35.929 | J3: 1002.96
A4: 2.2 | B4: 2.221 | C4: 7802.1 | D4: 8079.6 | E4: 108.561 | F4: 0.4784 | G4: 27172.54 | H4: 1.171 | I4: 34.785 | J4: 966.019
A5: 2.3 | B5: 2.321 | C5: 8220.95 | D5: 8508 | E5: 108.575 | F5: 0.4821 | G5: 13640.47 | H5: 1.225 | I5: 33.74 | J5: 931.89
A6: 2.4 | B6: 2.421 | C6: 8639.8 | D6: 8940.2 | E6: 108.585 | F6: 0.4857 | G6: 6874.4394 | H6: 1.279 | I6: 32.765 | J6: 900.359
A7: 2.5 | B7: 2.521 | C7: 9064.1 | D7: 9376.1 | E7: 108.608 | F7: 0.4891 | G7: 3491.4297 | H7: 1.334 | I7: 31.86 | J7: 871.147
A8: 381.3875 | B8: 2.621 | C8: 9491.9 | D8: 9815.6 | E8: 108.636 | F8: 0.4925 | G8: 1799.9313 | H8: 1.388 | I8: 31.025 | J8: 1700.7735
A9: 760.275 | B9: 2.721 | C9: 9923.2 | D9: 10258.6 | E9: 108.67 | F9: 0.4958 | G9: 108.433 | H9: 1.443 | I9: 30.247 | J9: 2530.4
A10: 652.15 | B10: 2.821 | C10: 10357.9 | D10: 10705.2 | E10: 108.708 | F10: 0.4991 | G10: 108.446 | H10: 1.497 | I10: 29.519 | J10: 3360.0264
A11: 435.8 | B11: 2.921 | C11: 10795.8 | D11: 11155 | E11: 108.729 | F11: 0.5022 | G11: 108.46 | H11: 1.552 | I11: 28.837 | J11: 5900.7819
A12: 219.45 | B12: 3.021 | C12: 11236.6 | D12: 11607.8 | E12: 108.756 | F12: 0.5053 | G12: 108.471 | H12: 1.606 | I12: 28.191 | J12: 8441.5373
A13: 111.325 | B13: 3.121 | C13: 11680.3 | D13: 12063.7 | E13: 108.784 | F13: 0.5083 | G13: 108.483 | H13: 1.661 | I13: 27.576 | J13: 16109.301
... A66: 8.4 | B66: 8.421 | C66: 38112.8 | D66: 39267.5 | E66: 105983 | F66: 0.6131 | G66: 108.241 | H66: 4.553 | I66: 16.46 | J66: 339.765

Sheet Formula
A3: =IF(ISBLANK(Final!A3),"Y",IF(ISNUMBER(Final!$A2:'Final'!$A4),IF(OR(AND(NOT(ISBLANK(Final!A2)),NOT(ISBLANK(Final!A4)),ISNUMBER(Final!A2:'Final'!A4),Final!A3>Final!A2,Final!A3>Final!A4,Final!A3>Final!A5),AND(NOT(ISBLANK(Final!A2)),NOT(ISBLANK(Final!A4)),NOT(ISBLANK(Final!A5)),ISNUMBER(Final!A2:'Final'!A4),Final!A3<Final!A2,Final!A3>Final!A4,Final!A3<Final!A5),AND(NOT(ISBLANK(Final!A2)),NOT(ISBLANK(Final!A4)),ISNUMBER(Final!A2:'Final'!A4),Final!A3<Final!A2,Final!A3<Final!A1,Final!A3<Final!A4),AND(ISBLANK(Final!A2),NOT(ISBLANK(Final!A4)),ISNUMBER(Final!A2:'Final'!A4),Final!A3>Final!A2,Final!A3<Final!A4,Final!A3<Final!A1)),"Y","."),IF(OR(AND(Final!A3>Final!A2,Final!A3>Final!A4),AND(Final!A3<Final!A2,Final!A3<Final!A4)),IF(AND(Final!$A3=Final!$A2,Final!$A3=Final!$A4),IF(Final!A3=MAX((Final!$A$2:'Final'!$A$100000=Final!$A2),Final!A2:INDEX(Final!A2:'Final'!A100000,SUMPRODUCT(--EXACT(Final!$A3,Final!$A2:'Final'!$A$100000)))),".","Y"),"."),"."))) -> . | B3: =IF(ISBLANK(Final!B3),"Y",IF(ISNUMBER(Final!$A2:'Final'!$A4),IF(OR(AND(NOT(ISBLANK(Final!B2)),NOT(ISBLANK(Final!B4)),ISNUMBER(Final!B2:'Final'!B4),Final!B3>Final!B2,Final!B3>Final!B4,Final!B3>Final!B5),AND(NOT(ISBLANK(Final!B2)),NOT(ISBLANK(Final!B4)),NOT(ISBLANK(Final!B5)),ISNUMBER(Final!B2:'Final'!B4),Final!B3<Final!B2,Final!B3>Final!B4,Final!B3<Final!B5),AND(NOT(ISBLANK(Final!B2)),NOT(ISBLANK(Final!B4)),ISNUMBER(Final!B2:'Final'!B4),Final!B3<Final!B2,Final!B3<Final!B1,Final!B3<Final!B4),AND(ISBLANK(Final!B2),NOT(ISBLANK(Final!B4)),ISNUMBER(Final!B2:'Final'!B4),Final!B3>Final!B2,Final!B3<Final!B4,Final!B3<Final!B1)),"Y","."),IF(OR(AND(Final!B3>Final!B2,Final!B3>Final!B4),AND(Final!B3<Final!B2,Final!B3<Final!B4)),IF(AND(Final!$A3=Final!$A2,Final!$A3=Final!$A4),IF(Final!B3=MAX((Final!$A$2:'Final'!$A$100000=Final!$A2),Final!B2:INDEX(Final!B2:'Final'!B100000,SUMPRODUCT(--EXACT(Final!$A3,Final!$A2:'Final'!$A$100000)))),".","Y"),"."),"."))) -> . | C3: =IF(ISBLANK(Final!C3),"Y",IF(ISNUMBER(Final!$A2:'Final'!$A4),IF(OR(AND(NOT(ISBLANK(Final!C2)),NOT(ISBLANK(Final!C4)),ISNUMBER(Final!C2:'Final'!C4),Final!C3>Final!C2,Final!C3>Final!C4,Final!C3>Final!C5),AND(NOT(ISBLANK(Final!C2)),NOT(ISBLANK(Final!C4)),NOT(ISBLANK(Final!C5)),ISNUMBER(Final!C2:'Final'!C4),Final!C3<Final!C2,Final!C3>Final!C4,Final!C3<Final!C5),AND(NOT(ISBLANK(Final!C2)),NOT(ISBLANK(Final!C4)),ISNUMBER(Final!C2:'Final'!C4),Final!C3<Final!C2,Final!C3<Final!C1,Final!C3<Final!C4),AND(ISBLANK(Final!C2),NOT(ISBLANK(Final!C4)),ISNUMBER(Final!C2:'Final'!C4),Final!C3>Final!C2,Final!C3<Final!C4,Final!C3<Final!C1)),"Y","."),IF(OR(AND(Final!C3>Final!C2,Final!C3>Final!C4),AND(Final!C3<Final!C2,Final!C3<Final!C4)),IF(AND(Final!$A3=Final!$A2,Final!$A3=Final!$A4),IF(Final!C3=MAX((Final!$A$2:'Final'!$A$100000=Final!$A2),Final!C2:INDEX(Final!C2:'Final'!C100000,SUMPRODUCT(--EXACT(Final!$A3,Final!$A2:'Final'!$A$100000)))),".","Y"),"."),"."))) -> . | D3: =IF(ISBLANK(Final!D3),"Y",IF(ISNUMBER(Final!$A2:'Final'!$A4),IF(OR(AND(NOT(ISBLANK(Final!D2)),NOT(ISBLANK(Final!D4)),ISNUMBER(Final!D2:'Final'!D4),Final!D3>Final!D2,Final!D3>Final!D4,Final!D3>Final!D5),AND(NOT(ISBLANK(Final!D2)),NOT(ISBLANK(Final!D4)),NOT(ISBLANK(Final!D5)),ISNUMBER(Final!D2:'Final'!D4),Final!D3<Final!D2,Final!D3>Final!D4,Final!D3<Final!D5),AND(NOT(ISBLANK(Final!D2)),NOT(ISBLANK(Final!D4)),ISNUMBER(Final!D2:'Final'!D4),Final!D3<Final!D2,Final!D3<Final!D1,Final!D3<Final!D4),AND(ISBLANK(Final!D2),NOT(ISBLANK(Final!D4)),ISNUMBER(Final!D2:'Final'!D4),Final!D3>Final!D2,Final!D3<Final!D4,Final!D3<Final!D1)),"Y","."),IF(OR(AND(Final!D3>Final!D2,Final!D3>Final!D4),AND(Final!D3<Final!D2,Final!D3<Final!D4)),IF(AND(Final!$A3=Final!$A2,Final!$A3=Final!$A4),IF(Final!D3=MAX((Final!$A$2:'Final'!$A$100000=Final!$A2),Final!D2:INDEX(Final!D2:'Final'!D100000,SUMPRODUCT(--EXACT(Final!$A3,Final!$A2:'Final'!$A$100000)))),".","Y"),"."),"."))) -> . | E3: =IF(ISBLANK(Final!E3),"Y",IF(ISNUMBER(Final!$A2:'Final'!$A4),IF(OR(AND(NOT(ISBLANK(Final!E2)),NOT(ISBLANK(Final!E4)),ISNUMBER(Final!E2:'Final'!E4),Final!E3>Final!E2,Final!E3>Final!E4,Final!E3>Final!E5),AND(NOT(ISBLANK(Final!E2)),NOT(ISBLANK(Final!E4)),NOT(ISBLANK(Final!E5)),ISNUMBER(Final!E2:'Final'!E4),Final!E3<Final!E2,Final!E3>Final!E4,Final!E3<Final!E5),AND(NOT(ISBLANK(Final!E2)),NOT(ISBLANK(Final!E4)),ISNUMBER(Final!E2:'Final'!E4),Final!E3<Final!E2,Final!E3<Final!E1,Final!E3<Final!E4),AND(ISBLANK(Final!E2),NOT(ISBLANK(Final!E4)),ISNUMBER(Final!E2:'Final'!E4),Final!E3>Final!E2,Final!E3<Final!E4,Final!E3<Final!E1)),"Y","."),IF(OR(AND(Final!E3>Final!E2,Final!E3>Final!E4),AND(Final!E3<Final!E2,Final!E3<Final!E4)),IF(AND(Final!$A3=Final!$A2,Final!$A3=Final!$A4),IF(Final!E3=MAX((Final!$A$2:'Final'!$A$100000=Final!$A2),Final!E2:INDEX(Final!E2:'Final'!E100000,SUMPRODUCT(--EXACT(Final!$A3,Final!$A2:'Final'!$A$100000)))),".","Y"),"."),"."))) -> . | F3: =IF(ISBLANK(Final!F3),"Y",IF(ISNUMBER(Final!$A2:'Final'!$A4),IF(OR(AND(NOT(ISBLANK(Final!F2)),NOT(ISBLANK(Final!F4)),ISNUMBER(Final!F2:'Final'!F4),Final!F3>Final!F2,Final!F3>Final!F4,Final!F3>Final!F5),AND(NOT(ISBLANK(Final!F2)),NOT(ISBLANK(Final!F4)),NOT(ISBLANK(Final!F5)),ISNUMBER(Final!F2:'Final'!F4),Final!F3<Final!F2,Final!F3>Final!F4,Final!F3<Final!F5),AND(NOT(ISBLANK(Final!F2)),NOT(ISBLANK(Final!F4)),ISNUMBER(Final!F2:'Final'!F4),Final!F3<Final!F2,Final!F3<Final!F1,Final!F3<Final!F4),AND(ISBLANK(Final!F2),NOT(ISBLANK(Final!F4)),ISNUMBER(Final!F2:'Final'!F4),Final!F3>Final!F2,Final!F3<Final!F4,Final!F3<Final!F1)),"Y","."),IF(OR(AND(Final!F3>Final!F2,Final!F3>Final!F4),AND(Final!F3<Final!F2,Final!F3<Final!F4)),IF(AND(Final!$A3=Final!$A2,Final!$A3=Final!$A4),IF(Final!F3=MAX((Final!$A$2:'Final'!$A$100000=Final!$A2),Final!F2:INDEX(Final!F2:'Final'!F100000,SUMPRODUCT(--EXACT(Final!$A3,Final!$A2:'Final'!$A$100000)))),".","Y"),"."),"."))) -> . | G3: =IF(ISBLANK(Final!G3),"Y",IF(ISNUMBER(Final!$A2:'Final'!$A4),IF(OR(AND(NOT(ISBLANK(Final!G2)),NOT(ISBLANK(Final!G4)),ISNUMBER(Final!G2:'Final'!G4),Final!G3>Final!G2,Final!G3>Final!G4,Final!G3>Final!G5),AND(NOT(ISBLANK(Final!G2)),NOT(ISBLANK(Final!G4)),NOT(ISBLANK(Final!G5)),ISNUMBER(Final!G2:'Final'!G4),Final!G3<Final!G2,Final!G3>Final!G4,Final!G3<Final!G5),AND(NOT(ISBLANK(Final!G2)),NOT(ISBLANK(Final!G4)),ISNUMBER(Final!G2:'Final'!G4),Final!G3<Final!G2,Final!G3<Final!G1,Final!G3<Final!G4),AND(ISBLANK(Final!G2),NOT(ISBLANK(Final!G4)),ISNUMBER(Final!G2:'Final'!G4),Final!G3>Final!G2,Final!G3<Final!G4,Final!G3<Final!G1)),"Y","."),IF(OR(AND(Final!G3>Final!G2,Final!G3>Final!G4),AND(Final!G3<Final!G2,Final!G3<Final!G4)),IF(AND(Final!$A3=Final!$A2,Final!$A3=Final!$A4),IF(Final!G3=MAX((Final!$A$2:'Final'!$A$100000=Final!$A2),Final!G2:INDEX(Final!G2:'Final'!G100000,SUMPRODUCT(--EXACT(Final!$A3,Final!$A2:'Final'!$A$100000)))),".","Y"),"."),"."))) -> . | H3: =IF(ISBLANK(Final!H3),"Y",IF(ISNUMBER(Final!$A2:'Final'!$A4),IF(OR(AND(NOT(ISBLANK(Final!H2)),NOT(ISBLANK(Final!H4)),ISNUMBER(Final!H2:'Final'!H4),Final!H3>Final!H2,Final!H3>Final!H4,Final!H3>Final!H5),AND(NOT(ISBLANK(Final!H2)),NOT(ISBLANK(Final!H4)),NOT(ISBLANK(Final!H5)),ISNUMBER(Final!H2:'Final'!H4),Final!H3<Final!H2,Final!H3>Final!H4,Final!H3<Final!H5),AND(NOT(ISBLANK(Final!H2)),NOT(ISBLANK(Final!H4)),ISNUMBER(Final!H2:'Final'!H4),Final!H3<Final!H2,Final!H3<Final!H1,Final!H3<Final!H4),AND(ISBLANK(Final!H2),NOT(ISBLANK(Final!H4)),ISNUMBER(Final!H2:'Final'!H4),Final!H3>Final!H2,Final!H3<Final!H4,Final!H3<Final!H1)),"Y","."),IF(OR(AND(Final!H3>Final!H2,Final!H3>Final!H4),AND(Final!H3<Final!H2,Final!H3<Final!H4)),IF(AND(Final!$A3=Final!$A2,Final!$A3=Final!$A4),IF(Final!H3=MAX((Final!$A$2:'Final'!$A$100000=Final!$A2),Final!H2:INDEX(Final!H2:'Final'!H100000,SUMPRODUCT(--EXACT(Final!$A3,Final!$A2:'Final'!$A$100000)))),".","Y"),"."),"."))) -> . | ... J3: =IF(ISBLANK(Final!J3),"Y",IF(ISNUMBER(Final!$A2:'Final'!$A4),IF(OR(AND(NOT(ISBLANK(Final!J2)),NOT(ISBLANK(Final!J4)),ISNUMBER(Final!J2:'Final'!J4),Final!J3>Final!J2,Final!J3>Final!J4,Final!J3>Final!J5),AND(NOT(ISBLANK(Final!J2)),NOT(ISBLANK(Final!J4)),NOT(ISBLANK(Final!J5)),ISNUMBER(Final!J2:'Final'!J4),Final!J3<Final!J2,Final!J3>Final!J4,Final!J3<Final!J5),AND(NOT(ISBLANK(Final!J2)),NOT(ISBLANK(Final!J4)),ISNUMBER(Final!J2:'Final'!J4),Final!J3<Final!J2,Final!J3<Final!J1,Final!J3<Final!J4),AND(ISBLANK(Final!J2),NOT(ISBLANK(Final!J4)),ISNUMBER(Final!J2:'Final'!J4),Final!J3>Final!J2,Final!J3<Final!J4,Final!J3<Final!J1)),"Y","."),IF(OR(AND(Final!J3>Final!J2,Final!J3>Final!J4),AND(Final!J3<Final!J2,Final!J3<Final!J4)),IF(AND(Final!$A3=Final!$A2,Final!$A3=Final!$A4),IF(Final!J3=MAX((Final!$A$2:'Final'!$A$100000=Final!$A2),Final!J2:INDEX(Final!J2:'Final'!J100000,SUMPRODUCT(--EXACT(Final!$A3,Final!$A2:'Final'!$A$100000)))),".","Y"),"."),"."))) -> .
A4: =IF(ISBLANK(Final!A4),"Y",IF(ISNUMBER(Final!$A3:'Final'!$A5),IF(OR(AND(NOT(ISBLANK(Final!A3)),NOT(ISBLANK(Final!A5)),ISNUMBER(Final!A3:'Final'!A5),Final!A4>Final!A3,Final!A4>Final!A5,Final!A4>Final!A6),AND(NOT(ISBLANK(Final!A3)),NOT(ISBLANK(Final!A5)),NOT(ISBLANK(Final!A6)),ISNUMBER(Final!A3:'Final'!A5),Final!A4<Final!A3,Final!A4>Final!A5,Final!A4<Final!A6),AND(NOT(ISBLANK(Final!A3)),NOT(ISBLANK(Final!A5)),ISNUMBER(Final!A3:'Final'!A5),Final!A4<Final!A3,Final!A4<Final!A2,Final!A4<Final!A5),AND(ISBLANK(Final!A3),NOT(ISBLANK(Final!A5)),ISNUMBER(Final!A3:'Final'!A5),Final!A4>Final!A3,Final!A4<Final!A5,Final!A4<Final!A2)),"Y","."),IF(OR(AND(Final!A4>Final!A3,Final!A4>Final!A5),AND(Final!A4<Final!A3,Final!A4<Final!A5)),IF(AND(Final!$A4=Final!$A3,Final!$A4=Final!$A5),IF(Final!A4=MAX((Final!$A$2:'Final'!$A$100000=Final!$A3),Final!A3:INDEX(Final!A3:'Final'!A100001,SUMPRODUCT(--EXACT(Final!$A4,Final!$A3:'Final'!$A$100000)))),".","Y"),"."),"."))) -> . | B4: =IF(ISBLANK(Final!B4),"Y",IF(ISNUMBER(Final!$A3:'Final'!$A5),IF(OR(AND(NOT(ISBLANK(Final!B3)),NOT(ISBLANK(Final!B5)),ISNUMBER(Final!B3:'Final'!B5),Final!B4>Final!B3,Final!B4>Final!B5,Final!B4>Final!B6),AND(NOT(ISBLANK(Final!B3)),NOT(ISBLANK(Final!B5)),NOT(ISBLANK(Final!B6)),ISNUMBER(Final!B3:'Final'!B5),Final!B4<Final!B3,Final!B4>Final!B5,Final!B4<Final!B6),AND(NOT(ISBLANK(Final!B3)),NOT(ISBLANK(Final!B5)),ISNUMBER(Final!B3:'Final'!B5),Final!B4<Final!B3,Final!B4<Final!B2,Final!B4<Final!B5),AND(ISBLANK(Final!B3),NOT(ISBLANK(Final!B5)),ISNUMBER(Final!B3:'Final'!B5),Final!B4>Final!B3,Final!B4<Final!B5,Final!B4<Final!B2)),"Y","."),IF(OR(AND(Final!B4>Final!B3,Final!B4>Final!B5),AND(Final!B4<Final!B3,Final!B4<Final!B5)),IF(AND(Final!$A4=Final!$A3,Final!$A4=Final!$A5),IF(Final!B4=MAX((Final!$A$2:'Final'!$A$100000=Final!$A3),Final!B3:INDEX(Final!B3:'Final'!B100001,SUMPRODUCT(--EXACT(Final!$A4,Final!$A3:'Final'!$A$100000)))),".","Y"),"."),"."))) -> . | C4: =IF(ISBLANK(Final!C4),"Y",IF(ISNUMBER(Final!$A3:'Final'!$A5),IF(OR(AND(NOT(ISBLANK(Final!C3)),NOT(ISBLANK(Final!C5)),ISNUMBER(Final!C3:'Final'!C5),Final!C4>Final!C3,Final!C4>Final!C5,Final!C4>Final!C6),AND(NOT(ISBLANK(Final!C3)),NOT(ISBLANK(Final!C5)),NOT(ISBLANK(Final!C6)),ISNUMBER(Final!C3:'Final'!C5),Final!C4<Final!C3,Final!C4>Final!C5,Final!C4<Final!C6),AND(NOT(ISBLANK(Final!C3)),NOT(ISBLANK(Final!C5)),ISNUMBER(Final!C3:'Final'!C5),Final!C4<Final!C3,Final!C4<Final!C2,Final!C4<Final!C5),AND(ISBLANK(Final!C3),NOT(ISBLANK(Final!C5)),ISNUMBER(Final!C3:'Final'!C5),Final!C4>Final!C3,Final!C4<Final!C5,Final!C4<Final!C2)),"Y","."),IF(OR(AND(Final!C4>Final!C3,Final!C4>Final!C5),AND(Final!C4<Final!C3,Final!C4<Final!C5)),IF(AND(Final!$A4=Final!$A3,Final!$A4=Final!$A5),IF(Final!C4=MAX((Final!$A$2:'Final'!$A$100000=Final!$A3),Final!C3:INDEX(Final!C3:'Final'!C100001,SUMPRODUCT(--EXACT(Final!$A4,Final!$A3:'Final'!$A$100000)))),".","Y"),"."),"."))) -> . | D4: =IF(ISBLANK(Final!D4),"Y",IF(ISNUMBER(Final!$A3:'Final'!$A5),IF(OR(AND(NOT(ISBLANK(Final!D3)),NOT(ISBLANK(Final!D5)),ISNUMBER(Final!D3:'Final'!D5),Final!D4>Final!D3,Final!D4>Final!D5,Final!D4>Final!D6),AND(NOT(ISBLANK(Final!D3)),NOT(ISBLANK(Final!D5)),NOT(ISBLANK(Final!D6)),ISNUMBER(Final!D3:'Final'!D5),Final!D4<Final!D3,Final!D4>Final!D5,Final!D4<Final!D6),AND(NOT(ISBLANK(Final!D3)),NOT(ISBLANK(Final!D5)),ISNUMBER(Final!D3:'Final'!D5),Final!D4<Final!D3,Final!D4<Final!D2,Final!D4<Final!D5),AND(ISBLANK(Final!D3),NOT(ISBLANK(Final!D5)),ISNUMBER(Final!D3:'Final'!D5),Final!D4>Final!D3,Final!D4<Final!D5,Final!D4<Final!D2)),"Y","."),IF(OR(AND(Final!D4>Final!D3,Final!D4>Final!D5),AND(Final!D4<Final!D3,Final!D4<Final!D5)),IF(AND(Final!$A4=Final!$A3,Final!$A4=Final!$A5),IF(Final!D4=MAX((Final!$A$2:'Final'!$A$100000=Final!$A3),Final!D3:INDEX(Final!D3:'Final'!D100001,SUMPRODUCT(--EXACT(Final!$A4,Final!$A3:'Final'!$A$100000)))),".","Y"),"."),"."))) -> . | E4: =IF(ISBLANK(Final!E4),"Y",IF(ISNUMBER(Final!$A3:'Final'!$A5),IF(OR(AND(NOT(ISBLANK(Final!E3)),NOT(ISBLANK(Final!E5)),ISNUMBER(Final!E3:'Final'!E5),Final!E4>Final!E3,Final!E4>Final!E5,Final!E4>Final!E6),AND(NOT(ISBLANK(Final!E3)),NOT(ISBLANK(Final!E5)),NOT(ISBLANK(Final!E6)),ISNUMBER(Final!E3:'Final'!E5),Final!E4<Final!E3,Final!E4>Final!E5,Final!E4<Final!E6),AND(NOT(ISBLANK(Final!E3)),NOT(ISBLANK(Final!E5)),ISNUMBER(Final!E3:'Final'!E5),Final!E4<Final!E3,Final!E4<Final!E2,Final!E4<Final!E5),AND(ISBLANK(Final!E3),NOT(ISBLANK(Final!E5)),ISNUMBER(Final!E3:'Final'!E5),Final!E4>Final!E3,Final!E4<Final!E5,Final!E4<Final!E2)),"Y","."),IF(OR(AND(Final!E4>Final!E3,Final!E4>Final!E5),AND(Final!E4<Final!E3,Final!E4<Final!E5)),IF(AND(Final!$A4=Final!$A3,Final!$A4=Final!$A5),IF(Final!E4=MAX((Final!$A$2:'Final'!$A$100000=Final!$A3),Final!E3:INDEX(Final!E3:'Final'!E100001,SUMPRODUCT(--EXACT(Final!$A4,Final!$A3:'Final'!$A$100000)))),".","Y"),"."),"."))) -> . | F4: =IF(ISBLANK(Final!F4),"Y",IF(ISNUMBER(Final!$A3:'Final'!$A5),IF(OR(AND(NOT(ISBLANK(Final!F3)),NOT(ISBLANK(Final!F5)),ISNUMBER(Final!F3:'Final'!F5),Final!F4>Final!F3,Final!F4>Final!F5,Final!F4>Final!F6),AND(NOT(ISBLANK(Final!F3)),NOT(ISBLANK(Final!F5)),NOT(ISBLANK(Final!F6)),ISNUMBER(Final!F3:'Final'!F5),Final!F4<Final!F3,Final!F4>Final!F5,Final!F4<Final!F6),AND(NOT(ISBLANK(Final!F3)),NOT(ISBLANK(Final!F5)),ISNUMBER(Final!F3:'Final'!F5),Final!F4<Final!F3,Final!F4<Final!F2,Final!F4<Final!F5),AND(ISBLANK(Final!F3),NOT(ISBLANK(Final!F5)),ISNUMBER(Final!F3:'Final'!F5),Final!F4>Final!F3,Final!F4<Final!F5,Final!F4<Final!F2)),"Y","."),IF(OR(AND(Final!F4>Final!F3,Final!F4>Final!F5),AND(Final!F4<Final!F3,Final!F4<Final!F5)),IF(AND(Final!$A4=Final!$A3,Final!$A4=Final!$A5),IF(Final!F4=MAX((Final!$A$2:'Final'!$A$100000=Final!$A3),Final!F3:INDEX(Final!F3:'Final'!F100001,SUMPRODUCT(--EXACT(Final!$A4,Final!$A3:'Final'!$A$100000)))),".","Y"),"."),"."))) -> . | G4: =IF(ISBLANK(Final!G4),"Y",IF(ISNUMBER(Final!$A3:'Final'!$A5),IF(OR(AND(NOT(ISBLANK(Final!G3)),NOT(ISBLANK(Final!G5)),ISNUMBER(Final!G3:'Final'!G5),Final!G4>Final!G3,Final!G4>Final!G5,Final!G4>Final!G6),AND(NOT(ISBLANK(Final!G3)),NOT(ISBLANK(Final!G5)),NOT(ISBLANK(Final!G6)),ISNUMBER(Final!G3:'Final'!G5),Final!G4<Final!G3,Final!G4>Final!G5,Final!G4<Final!G6),AND(NOT(ISBLANK(Final!G3)),NOT(ISBLANK(Final!G5)),ISNUMBER(Final!G3:'Final'!G5),Final!G4<Final!G3,Final!G4<Final!G2,Final!G4<Final!G5),AND(ISBLANK(Final!G3),NOT(ISBLANK(Final!G5)),ISNUMBER(Final!G3:'Final'!G5),Final!G4>Final!G3,Final!G4<Final!G5,Final!G4<Final!G2)),"Y","."),IF(OR(AND(Final!G4>Final!G3,Final!G4>Final!G5),AND(Final!G4<Final!G3,Final!G4<Final!G5)),IF(AND(Final!$A4=Final!$A3,Final!$A4=Final!$A5),IF(Final!G4=MAX((Final!$A$2:'Final'!$A$100000=Final!$A3),Final!G3:INDEX(Final!G3:'Final'!G100001,SUMPRODUCT(--EXACT(Final!$A4,Final!$A3:'Final'!$A$100000)))),".","Y"),"."),"."))) -> . | H4: =IF(ISBLANK(Final!H4),"Y",IF(ISNUMBER(Final!$A3:'Final'!$A5),IF(OR(AND(NOT(ISBLANK(Final!H3)),NOT(ISBLANK(Final!H5)),ISNUMBER(Final!H3:'Final'!H5),Final!H4>Final!H3,Final!H4>Final!H5,Final!H4>Final!H6),AND(NOT(ISBLANK(Final!H3)),NOT(ISBLANK(Final!H5)),NOT(ISBLANK(Final!H6)),ISNUMBER(Final!H3:'Final'!H5),Final!H4<Final!H3,Final!H4>Final!H5,Final!H4<Final!H6),AND(NOT(ISBLANK(Final!H3)),NOT(ISBLANK(Final!H5)),ISNUMBER(Final!H3:'Final'!H5),Final!H4<Final!H3,Final!H4<Final!H2,Final!H4<Final!H5),AND(ISBLANK(Final!H3),NOT(ISBLANK(Final!H5)),ISNUMBER(Final!H3:'Final'!H5),Final!H4>Final!H3,Final!H4<Final!H5,Final!H4<Final!H2)),"Y","."),IF(OR(AND(Final!H4>Final!H3,Final!H4>Final!H5),AND(Final!H4<Final!H3,Final!H4<Final!H5)),IF(AND(Final!$A4=Final!$A3,Final!$A4=Final!$A5),IF(Final!H4=MAX((Final!$A$2:'Final'!$A$100000=Final!$A3),Final!H3:INDEX(Final!H3:'Final'!H100001,SUMPRODUCT(--EXACT(Final!$A4,Final!$A3:'Final'!$A$100000)))),".","Y"),"."),"."))) -> . | ... J4: =IF(ISBLANK(Final!J4),"Y",IF(ISNUMBER(Final!$A3:'Final'!$A5),IF(OR(AND(NOT(ISBLANK(Final!J3)),NOT(ISBLANK(Final!J5)),ISNUMBER(Final!J3:'Final'!J5),Final!J4>Final!J3,Final!J4>Final!J5,Final!J4>Final!J6),AND(NOT(ISBLANK(Final!J3)),NOT(ISBLANK(Final!J5)),NOT(ISBLANK(Final!J6)),ISNUMBER(Final!J3:'Final'!J5),Final!J4<Final!J3,Final!J4>Final!J5,Final!J4<Final!J6),AND(NOT(ISBLANK(Final!J3)),NOT(ISBLANK(Final!J5)),ISNUMBER(Final!J3:'Final'!J5),Final!J4<Final!J3,Final!J4<Final!J2,Final!J4<Final!J5),AND(ISBLANK(Final!J3),NOT(ISBLANK(Final!J5)),ISNUMBER(Final!J3:'Final'!J5),Final!J4>Final!J3,Final!J4<Final!J5,Final!J4<Final!J2)),"Y","."),IF(OR(AND(Final!J4>Final!J3,Final!J4>Final!J5),AND(Final!J4<Final!J3,Final!J4<Final!J5)),IF(AND(Final!$A4=Final!$A3,Final!$A4=Final!$A5),IF(Final!J4=MAX((Final!$A$2:'Final'!$A$100000=Final!$A3),Final!J3:INDEX(Final!J3:'Final'!J100001,SUMPRODUCT(--EXACT(Final!$A4,Final!$A3:'Final'!$A$100000)))),".","Y"),"."),"."))) -> .
A5: =IF(ISBLANK(Final!A5),"Y",IF(ISNUMBER(Final!$A4:'Final'!$A6),IF(OR(AND(NOT(ISBLANK(Final!A4)),NOT(ISBLANK(Final!A6)),ISNUMBER(Final!A4:'Final'!A6),Final!A5>Final!A4,Final!A5>Final!A6,Final!A5>Final!A7),AND(NOT(ISBLANK(Final!A4)),NOT(ISBLANK(Final!A6)),NOT(ISBLANK(Final!A7)),ISNUMBER(Final!A4:'Final'!A6),Final!A5<Final!A4,Final!A5>Final!A6,Final!A5<Final!A7),AND(NOT(ISBLANK(Final!A4)),NOT(ISBLANK(Final!A6)),ISNUMBER(Final!A4:'Final'!A6),Final!A5<Final!A4,Final!A5<Final!A3,Final!A5<Final!A6),AND(ISBLANK(Final!A4),NOT(ISBLANK(Final!A6)),ISNUMBER(Final!A4:'Final'!A6),Final!A5>Final!A4,Final!A5<Final!A6,Final!A5<Final!A3)),"Y","."),IF(OR(AND(Final!A5>Final!A4,Final!A5>Final!A6),AND(Final!A5<Final!A4,Final!A5<Final!A6)),IF(AND(Final!$A5=Final!$A4,Final!$A5=Final!$A6),IF(Final!A5=MAX((Final!$A$2:'Final'!$A$100000=Final!$A4),Final!A4:INDEX(Final!A4:'Final'!A100002,SUMPRODUCT(--EXACT(Final!$A5,Final!$A4:'Final'!$A$100000)))),".","Y"),"."),"."))) -> . | B5: =IF(ISBLANK(Final!B5),"Y",IF(ISNUMBER(Final!$A4:'Final'!$A6),IF(OR(AND(NOT(ISBLANK(Final!B4)),NOT(ISBLANK(Final!B6)),ISNUMBER(Final!B4:'Final'!B6),Final!B5>Final!B4,Final!B5>Final!B6,Final!B5>Final!B7),AND(NOT(ISBLANK(Final!B4)),NOT(ISBLANK(Final!B6)),NOT(ISBLANK(Final!B7)),ISNUMBER(Final!B4:'Final'!B6),Final!B5<Final!B4,Final!B5>Final!B6,Final!B5<Final!B7),AND(NOT(ISBLANK(Final!B4)),NOT(ISBLANK(Final!B6)),ISNUMBER(Final!B4:'Final'!B6),Final!B5<Final!B4,Final!B5<Final!B3,Final!B5<Final!B6),AND(ISBLANK(Final!B4),NOT(ISBLANK(Final!B6)),ISNUMBER(Final!B4:'Final'!B6),Final!B5>Final!B4,Final!B5<Final!B6,Final!B5<Final!B3)),"Y","."),IF(OR(AND(Final!B5>Final!B4,Final!B5>Final!B6),AND(Final!B5<Final!B4,Final!B5<Final!B6)),IF(AND(Final!$A5=Final!$A4,Final!$A5=Final!$A6),IF(Final!B5=MAX((Final!$A$2:'Final'!$A$100000=Final!$A4),Final!B4:INDEX(Final!B4:'Final'!B100002,SUMPRODUCT(--EXACT(Final!$A5,Final!$A4:'Final'!$A$100000)))),".","Y"),"."),"."))) -> . | C5: =IF(ISBLANK(Final!C5),"Y",IF(ISNUMBER(Final!$A4:'Final'!$A6),IF(OR(AND(NOT(ISBLANK(Final!C4)),NOT(ISBLANK(Final!C6)),ISNUMBER(Final!C4:'Final'!C6),Final!C5>Final!C4,Final!C5>Final!C6,Final!C5>Final!C7),AND(NOT(ISBLANK(Final!C4)),NOT(ISBLANK(Final!C6)),NOT(ISBLANK(Final!C7)),ISNUMBER(Final!C4:'Final'!C6),Final!C5<Final!C4,Final!C5>Final!C6,Final!C5<Final!C7),AND(NOT(ISBLANK(Final!C4)),NOT(ISBLANK(Final!C6)),ISNUMBER(Final!C4:'Final'!C6),Final!C5<Final!C4,Final!C5<Final!C3,Final!C5<Final!C6),AND(ISBLANK(Final!C4),NOT(ISBLANK(Final!C6)),ISNUMBER(Final!C4:'Final'!C6),Final!C5>Final!C4,Final!C5<Final!C6,Final!C5<Final!C3)),"Y","."),IF(OR(AND(Final!C5>Final!C4,Final!C5>Final!C6),AND(Final!C5<Final!C4,Final!C5<Final!C6)),IF(AND(Final!$A5=Final!$A4,Final!$A5=Final!$A6),IF(Final!C5=MAX((Final!$A$2:'Final'!$A$100000=Final!$A4),Final!C4:INDEX(Final!C4:'Final'!C100002,SUMPRODUCT(--EXACT(Final!$A5,Final!$A4:'Final'!$A$100000)))),".","Y"),"."),"."))) -> . | D5: =IF(ISBLANK(Final!D5),"Y",IF(ISNUMBER(Final!$A4:'Final'!$A6),IF(OR(AND(NOT(ISBLANK(Final!D4)),NOT(ISBLANK(Final!D6)),ISNUMBER(Final!D4:'Final'!D6),Final!D5>Final!D4,Final!D5>Final!D6,Final!D5>Final!D7),AND(NOT(ISBLANK(Final!D4)),NOT(ISBLANK(Final!D6)),NOT(ISBLANK(Final!D7)),ISNUMBER(Final!D4:'Final'!D6),Final!D5<Final!D4,Final!D5>Final!D6,Final!D5<Final!D7),AND(NOT(ISBLANK(Final!D4)),NOT(ISBLANK(Final!D6)),ISNUMBER(Final!D4:'Final'!D6),Final!D5<Final!D4,Final!D5<Final!D3,Final!D5<Final!D6),AND(ISBLANK(Final!D4),NOT(ISBLANK(Final!D6)),ISNUMBER(Final!D4:'Final'!D6),Final!D5>Final!D4,Final!D5<Final!D6,Final!D5<Final!D3)),"Y","."),IF(OR(AND(Final!D5>Final!D4,Final!D5>Final!D6),AND(Final!D5<Final!D4,Final!D5<Final!D6)),IF(AND(Final!$A5=Final!$A4,Final!$A5=Final!$A6),IF(Final!D5=MAX((Final!$A$2:'Final'!$A$100000=Final!$A4),Final!D4:INDEX(Final!D4:'Final'!D100002,SUMPRODUCT(--EXACT(Final!$A5,Final!$A4:'Final'!$A$100000)))),".","Y"),"."),"."))) -> . | E5: =IF(ISBLANK(Final!E5),"Y",IF(ISNUMBER(Final!$A4:'Final'!$A6),IF(OR(AND(NOT(ISBLANK(Final!E4)),NOT(ISBLANK(Final!E6)),ISNUMBER(Final!E4:'Final'!E6),Final!E5>Final!E4,Final!E5>Final!E6,Final!E5>Final!E7),AND(NOT(ISBLANK(Final!E4)),NOT(ISBLANK(Final!E6)),NOT(ISBLANK(Final!E7)),ISNUMBER(Final!E4:'Final'!E6),Final!E5<Final!E4,Final!E5>Final!E6,Final!E5<Final!E7),AND(NOT(ISBLANK(Final!E4)),NOT(ISBLANK(Final!E6)),ISNUMBER(Final!E4:'Final'!E6),Final!E5<Final!E4,Final!E5<Final!E3,Final!E5<Final!E6),AND(ISBLANK(Final!E4),NOT(ISBLANK(Final!E6)),ISNUMBER(Final!E4:'Final'!E6),Final!E5>Final!E4,Final!E5<Final!E6,Final!E5<Final!E3)),"Y","."),IF(OR(AND(Final!E5>Final!E4,Final!E5>Final!E6),AND(Final!E5<Final!E4,Final!E5<Final!E6)),IF(AND(Final!$A5=Final!$A4,Final!$A5=Final!$A6),IF(Final!E5=MAX((Final!$A$2:'Final'!$A$100000=Final!$A4),Final!E4:INDEX(Final!E4:'Final'!E100002,SUMPRODUCT(--EXACT(Final!$A5,Final!$A4:'Final'!$A$100000)))),".","Y"),"."),"."))) -> . | F5: =IF(ISBLANK(Final!F5),"Y",IF(ISNUMBER(Final!$A4:'Final'!$A6),IF(OR(AND(NOT(ISBLANK(Final!F4)),NOT(ISBLANK(Final!F6)),ISNUMBER(Final!F4:'Final'!F6),Final!F5>Final!F4,Final!F5>Final!F6,Final!F5>Final!F7),AND(NOT(ISBLANK(Final!F4)),NOT(ISBLANK(Final!F6)),NOT(ISBLANK(Final!F7)),ISNUMBER(Final!F4:'Final'!F6),Final!F5<Final!F4,Final!F5>Final!F6,Final!F5<Final!F7),AND(NOT(ISBLANK(Final!F4)),NOT(ISBLANK(Final!F6)),ISNUMBER(Final!F4:'Final'!F6),Final!F5<Final!F4,Final!F5<Final!F3,Final!F5<Final!F6),AND(ISBLANK(Final!F4),NOT(ISBLANK(Final!F6)),ISNUMBER(Final!F4:'Final'!F6),Final!F5>Final!F4,Final!F5<Final!F6,Final!F5<Final!F3)),"Y","."),IF(OR(AND(Final!F5>Final!F4,Final!F5>Final!F6),AND(Final!F5<Final!F4,Final!F5<Final!F6)),IF(AND(Final!$A5=Final!$A4,Final!$A5=Final!$A6),IF(Final!F5=MAX((Final!$A$2:'Final'!$A$100000=Final!$A4),Final!F4:INDEX(Final!F4:'Final'!F100002,SUMPRODUCT(--EXACT(Final!$A5,Final!$A4:'Final'!$A$100000)))),".","Y"),"."),"."))) -> . | G5: =IF(ISBLANK(Final!G5),"Y",IF(ISNUMBER(Final!$A4:'Final'!$A6),IF(OR(AND(NOT(ISBLANK(Final!G4)),NOT(ISBLANK(Final!G6)),ISNUMBER(Final!G4:'Final'!G6),Final!G5>Final!G4,Final!G5>Final!G6,Final!G5>Final!G7),AND(NOT(ISBLANK(Final!G4)),NOT(ISBLANK(Final!G6)),NOT(ISBLANK(Final!G7)),ISNUMBER(Final!G4:'Final'!G6),Final!G5<Final!G4,Final!G5>Final!G6,Final!G5<Final!G7),AND(NOT(ISBLANK(Final!G4)),NOT(ISBLANK(Final!G6)),ISNUMBER(Final!G4:'Final'!G6),Final!G5<Final!G4,Final!G5<Final!G3,Final!G5<Final!G6),AND(ISBLANK(Final!G4),NOT(ISBLANK(Final!G6)),ISNUMBER(Final!G4:'Final'!G6),Final!G5>Final!G4,Final!G5<Final!G6,Final!G5<Final!G3)),"Y","."),IF(OR(AND(Final!G5>Final!G4,Final!G5>Final!G6),AND(Final!G5<Final!G4,Final!G5<Final!G6)),IF(AND(Final!$A5=Final!$A4,Final!$A5=Final!$A6),IF(Final!G5=MAX((Final!$A$2:'Final'!$A$100000=Final!$A4),Final!G4:INDEX(Final!G4:'Final'!G100002,SUMPRODUCT(--EXACT(Final!$A5,Final!$A4:'Final'!$A$100000)))),".","Y"),"."),"."))) -> . | H5: =IF(ISBLANK(Final!H5),"Y",IF(ISNUMBER(Final!$A4:'Final'!$A6),IF(OR(AND(NOT(ISBLANK(Final!H4)),NOT(ISBLANK(Final!H6)),ISNUMBER(Final!H4:'Final'!H6),Final!H5>Final!H4,Final!H5>Final!H6,Final!H5>Final!H7),AND(NOT(ISBLANK(Final!H4)),NOT(ISBLANK(Final!H6)),NOT(ISBLANK(Final!H7)),ISNUMBER(Final!H4:'Final'!H6),Final!H5<Final!H4,Final!H5>Final!H6,Final!H5<Final!H7),AND(NOT(ISBLANK(Final!H4)),NOT(ISBLANK(Final!H6)),ISNUMBER(Final!H4:'Final'!H6),Final!H5<Final!H4,Final!H5<Final!H3,Final!H5<Final!H6),AND(ISBLANK(Final!H4),NOT(ISBLANK(Final!H6)),ISNUMBER(Final!H4:'Final'!H6),Final!H5>Final!H4,Final!H5<Final!H6,Final!H5<Final!H3)),"Y","."),IF(OR(AND(Final!H5>Final!H4,Final!H5>Final!H6),AND(Final!H5<Final!H4,Final!H5<Final!H6)),IF(AND(Final!$A5=Final!$A4,Final!$A5=Final!$A6),IF(Final!H5=MAX((Final!$A$2:'Final'!$A$100000=Final!$A4),Final!H4:INDEX(Final!H4:'Final'!H100002,SUMPRODUCT(--EXACT(Final!$A5,Final!$A4:'Final'!$A$100000)))),".","Y"),"."),"."))) -> . | ... J5: =IF(ISBLANK(Final!J5),"Y",IF(ISNUMBER(Final!$A4:'Final'!$A6),IF(OR(AND(NOT(ISBLANK(Final!J4)),NOT(ISBLANK(Final!J6)),ISNUMBER(Final!J4:'Final'!J6),Final!J5>Final!J4,Final!J5>Final!J6,Final!J5>Final!J7),AND(NOT(ISBLANK(Final!J4)),NOT(ISBLANK(Final!J6)),NOT(ISBLANK(Final!J7)),ISNUMBER(Final!J4:'Final'!J6),Final!J5<Final!J4,Final!J5>Final!J6,Final!J5<Final!J7),AND(NOT(ISBLANK(Final!J4)),NOT(ISBLANK(Final!J6)),ISNUMBER(Final!J4:'Final'!J6),Final!J5<Final!J4,Final!J5<Final!J3,Final!J5<Final!J6),AND(ISBLANK(Final!J4),NOT(ISBLANK(Final!J6)),ISNUMBER(Final!J4:'Final'!J6),Final!J5>Final!J4,Final!J5<Final!J6,Final!J5<Final!J3)),"Y","."),IF(OR(AND(Final!J5>Final!J4,Final!J5>Final!J6),AND(Final!J5<Final!J4,Final!J5<Final!J6)),IF(AND(Final!$A5=Final!$A4,Final!$A5=Final!$A6),IF(Final!J5=MAX((Final!$A$2:'Final'!$A$100000=Final!$A4),Final!J4:INDEX(Final!J4:'Final'!J100002,SUMPRODUCT(--EXACT(Final!$A5,Final!$A4:'Final'!$A$100000)))),".","Y"),"."),"."))) -> .
A6: =IF(ISBLANK(Final!A6),"Y",IF(ISNUMBER(Final!$A5:'Final'!$A7),IF(OR(AND(NOT(ISBLANK(Final!A5)),NOT(ISBLANK(Final!A7)),ISNUMBER(Final!A5:'Final'!A7),Final!A6>Final!A5,Final!A6>Final!A7,Final!A6>Final!A8),AND(NOT(ISBLANK(Final!A5)),NOT(ISBLANK(Final!A7)),NOT(ISBLANK(Final!A8)),ISNUMBER(Final!A5:'Final'!A7),Final!A6<Final!A5,Final!A6>Final!A7,Final!A6<Final!A8),AND(NOT(ISBLANK(Final!A5)),NOT(ISBLANK(Final!A7)),ISNUMBER(Final!A5:'Final'!A7),Final!A6<Final!A5,Final!A6<Final!A4,Final!A6<Final!A7),AND(ISBLANK(Final!A5),NOT(ISBLANK(Final!A7)),ISNUMBER(Final!A5:'Final'!A7),Final!A6>Final!A5,Final!A6<Final!A7,Final!A6<Final!A4)),"Y","."),IF(OR(AND(Final!A6>Final!A5,Final!A6>Final!A7),AND(Final!A6<Final!A5,Final!A6<Final!A7)),IF(AND(Final!$A6=Final!$A5,Final!$A6=Final!$A7),IF(Final!A6=MAX((Final!$A$2:'Final'!$A$100000=Final!$A5),Final!A5:INDEX(Final!A5:'Final'!A100003,SUMPRODUCT(--EXACT(Final!$A6,Final!$A5:'Final'!$A$100000)))),".","Y"),"."),"."))) -> . | B6: =IF(ISBLANK(Final!B6),"Y",IF(ISNUMBER(Final!$A5:'Final'!$A7),IF(OR(AND(NOT(ISBLANK(Final!B5)),NOT(ISBLANK(Final!B7)),ISNUMBER(Final!B5:'Final'!B7),Final!B6>Final!B5,Final!B6>Final!B7,Final!B6>Final!B8),AND(NOT(ISBLANK(Final!B5)),NOT(ISBLANK(Final!B7)),NOT(ISBLANK(Final!B8)),ISNUMBER(Final!B5:'Final'!B7),Final!B6<Final!B5,Final!B6>Final!B7,Final!B6<Final!B8),AND(NOT(ISBLANK(Final!B5)),NOT(ISBLANK(Final!B7)),ISNUMBER(Final!B5:'Final'!B7),Final!B6<Final!B5,Final!B6<Final!B4,Final!B6<Final!B7),AND(ISBLANK(Final!B5),NOT(ISBLANK(Final!B7)),ISNUMBER(Final!B5:'Final'!B7),Final!B6>Final!B5,Final!B6<Final!B7,Final!B6<Final!B4)),"Y","."),IF(OR(AND(Final!B6>Final!B5,Final!B6>Final!B7),AND(Final!B6<Final!B5,Final!B6<Final!B7)),IF(AND(Final!$A6=Final!$A5,Final!$A6=Final!$A7),IF(Final!B6=MAX((Final!$A$2:'Final'!$A$100000=Final!$A5),Final!B5:INDEX(Final!B5:'Final'!B100003,SUMPRODUCT(--EXACT(Final!$A6,Final!$A5:'Final'!$A$100000)))),".","Y"),"."),"."))) -> . | C6: =IF(ISBLANK(Final!C6),"Y",IF(ISNUMBER(Final!$A5:'Final'!$A7),IF(OR(AND(NOT(ISBLANK(Final!C5)),NOT(ISBLANK(Final!C7)),ISNUMBER(Final!C5:'Final'!C7),Final!C6>Final!C5,Final!C6>Final!C7,Final!C6>Final!C8),AND(NOT(ISBLANK(Final!C5)),NOT(ISBLANK(Final!C7)),NOT(ISBLANK(Final!C8)),ISNUMBER(Final!C5:'Final'!C7),Final!C6<Final!C5,Final!C6>Final!C7,Final!C6<Final!C8),AND(NOT(ISBLANK(Final!C5)),NOT(ISBLANK(Final!C7)),ISNUMBER(Final!C5:'Final'!C7),Final!C6<Final!C5,Final!C6<Final!C4,Final!C6<Final!C7),AND(ISBLANK(Final!C5),NOT(ISBLANK(Final!C7)),ISNUMBER(Final!C5:'Final'!C7),Final!C6>Final!C5,Final!C6<Final!C7,Final!C6<Final!C4)),"Y","."),IF(OR(AND(Final!C6>Final!C5,Final!C6>Final!C7),AND(Final!C6<Final!C5,Final!C6<Final!C7)),IF(AND(Final!$A6=Final!$A5,Final!$A6=Final!$A7),IF(Final!C6=MAX((Final!$A$2:'Final'!$A$100000=Final!$A5),Final!C5:INDEX(Final!C5:'Final'!C100003,SUMPRODUCT(--EXACT(Final!$A6,Final!$A5:'Final'!$A$100000)))),".","Y"),"."),"."))) -> . | D6: =IF(ISBLANK(Final!D6),"Y",IF(ISNUMBER(Final!$A5:'Final'!$A7),IF(OR(AND(NOT(ISBLANK(Final!D5)),NOT(ISBLANK(Final!D7)),ISNUMBER(Final!D5:'Final'!D7),Final!D6>Final!D5,Final!D6>Final!D7,Final!D6>Final!D8),AND(NOT(ISBLANK(Final!D5)),NOT(ISBLANK(Final!D7)),NOT(ISBLANK(Final!D8)),ISNUMBER(Final!D5:'Final'!D7),Final!D6<Final!D5,Final!D6>Final!D7,Final!D6<Final!D8),AND(NOT(ISBLANK(Final!D5)),NOT(ISBLANK(Final!D7)),ISNUMBER(Final!D5:'Final'!D7),Final!D6<Final!D5,Final!D6<Final!D4,Final!D6<Final!D7),AND(ISBLANK(Final!D5),NOT(ISBLANK(Final!D7)),ISNUMBER(Final!D5:'Final'!D7),Final!D6>Final!D5,Final!D6<Final!D7,Final!D6<Final!D4)),"Y","."),IF(OR(AND(Final!D6>Final!D5,Final!D6>Final!D7),AND(Final!D6<Final!D5,Final!D6<Final!D7)),IF(AND(Final!$A6=Final!$A5,Final!$A6=Final!$A7),IF(Final!D6=MAX((Final!$A$2:'Final'!$A$100000=Final!$A5),Final!D5:INDEX(Final!D5:'Final'!D100003,SUMPRODUCT(--EXACT(Final!$A6,Final!$A5:'Final'!$A$100000)))),".","Y"),"."),"."))) -> . | E6: =IF(ISBLANK(Final!E6),"Y",IF(ISNUMBER(Final!$A5:'Final'!$A7),IF(OR(AND(NOT(ISBLANK(Final!E5)),NOT(ISBLANK(Final!E7)),ISNUMBER(Final!E5:'Final'!E7),Final!E6>Final!E5,Final!E6>Final!E7,Final!E6>Final!E8),AND(NOT(ISBLANK(Final!E5)),NOT(ISBLANK(Final!E7)),NOT(ISBLANK(Final!E8)),ISNUMBER(Final!E5:'Final'!E7),Final!E6<Final!E5,Final!E6>Final!E7,Final!E6<Final!E8),AND(NOT(ISBLANK(Final!E5)),NOT(ISBLANK(Final!E7)),ISNUMBER(Final!E5:'Final'!E7),Final!E6<Final!E5,Final!E6<Final!E4,Final!E6<Final!E7),AND(ISBLANK(Final!E5),NOT(ISBLANK(Final!E7)),ISNUMBER(Final!E5:'Final'!E7),Final!E6>Final!E5,Final!E6<Final!E7,Final!E6<Final!E4)),"Y","."),IF(OR(AND(Final!E6>Final!E5,Final!E6>Final!E7),AND(Final!E6<Final!E5,Final!E6<Final!E7)),IF(AND(Final!$A6=Final!$A5,Final!$A6=Final!$A7),IF(Final!E6=MAX((Final!$A$2:'Final'!$A$100000=Final!$A5),Final!E5:INDEX(Final!E5:'Final'!E100003,SUMPRODUCT(--EXACT(Final!$A6,Final!$A5:'Final'!$A$100000)))),".","Y"),"."),"."))) -> . | F6: =IF(ISBLANK(Final!F6),"Y",IF(ISNUMBER(Final!$A5:'Final'!$A7),IF(OR(AND(NOT(ISBLANK(Final!F5)),NOT(ISBLANK(Final!F7)),ISNUMBER(Final!F5:'Final'!F7),Final!F6>Final!F5,Final!F6>Final!F7,Final!F6>Final!F8),AND(NOT(ISBLANK(Final!F5)),NOT(ISBLANK(Final!F7)),NOT(ISBLANK(Final!F8)),ISNUMBER(Final!F5:'Final'!F7),Final!F6<Final!F5,Final!F6>Final!F7,Final!F6<Final!F8),AND(NOT(ISBLANK(Final!F5)),NOT(ISBLANK(Final!F7)),ISNUMBER(Final!F5:'Final'!F7),Final!F6<Final!F5,Final!F6<Final!F4,Final!F6<Final!F7),AND(ISBLANK(Final!F5),NOT(ISBLANK(Final!F7)),ISNUMBER(Final!F5:'Final'!F7),Final!F6>Final!F5,Final!F6<Final!F7,Final!F6<Final!F4)),"Y","."),IF(OR(AND(Final!F6>Final!F5,Final!F6>Final!F7),AND(Final!F6<Final!F5,Final!F6<Final!F7)),IF(AND(Final!$A6=Final!$A5,Final!$A6=Final!$A7),IF(Final!F6=MAX((Final!$A$2:'Final'!$A$100000=Final!$A5),Final!F5:INDEX(Final!F5:'Final'!F100003,SUMPRODUCT(--EXACT(Final!$A6,Final!$A5:'Final'!$A$100000)))),".","Y"),"."),"."))) -> . | G6: =IF(ISBLANK(Final!G6),"Y",IF(ISNUMBER(Final!$A5:'Final'!$A7),IF(OR(AND(NOT(ISBLANK(Final!G5)),NOT(ISBLANK(Final!G7)),ISNUMBER(Final!G5:'Final'!G7),Final!G6>Final!G5,Final!G6>Final!G7,Final!G6>Final!G8),AND(NOT(ISBLANK(Final!G5)),NOT(ISBLANK(Final!G7)),NOT(ISBLANK(Final!G8)),ISNUMBER(Final!G5:'Final'!G7),Final!G6<Final!G5,Final!G6>Final!G7,Final!G6<Final!G8),AND(NOT(ISBLANK(Final!G5)),NOT(ISBLANK(Final!G7)),ISNUMBER(Final!G5:'Final'!G7),Final!G6<Final!G5,Final!G6<Final!G4,Final!G6<Final!G7),AND(ISBLANK(Final!G5),NOT(ISBLANK(Final!G7)),ISNUMBER(Final!G5:'Final'!G7),Final!G6>Final!G5,Final!G6<Final!G7,Final!G6<Final!G4)),"Y","."),IF(OR(AND(Final!G6>Final!G5,Final!G6>Final!G7),AND(Final!G6<Final!G5,Final!G6<Final!G7)),IF(AND(Final!$A6=Final!$A5,Final!$A6=Final!$A7),IF(Final!G6=MAX((Final!$A$2:'Final'!$A$100000=Final!$A5),Final!G5:INDEX(Final!G5:'Final'!G100003,SUMPRODUCT(--EXACT(Final!$A6,Final!$A5:'Final'!$A$100000)))),".","Y"),"."),"."))) -> . | H6: =IF(ISBLANK(Final!H6),"Y",IF(ISNUMBER(Final!$A5:'Final'!$A7),IF(OR(AND(NOT(ISBLANK(Final!H5)),NOT(ISBLANK(Final!H7)),ISNUMBER(Final!H5:'Final'!H7),Final!H6>Final!H5,Final!H6>Final!H7,Final!H6>Final!H8),AND(NOT(ISBLANK(Final!H5)),NOT(ISBLANK(Final!H7)),NOT(ISBLANK(Final!H8)),ISNUMBER(Final!H5:'Final'!H7),Final!H6<Final!H5,Final!H6>Final!H7,Final!H6<Final!H8),AND(NOT(ISBLANK(Final!H5)),NOT(ISBLANK(Final!H7)),ISNUMBER(Final!H5:'Final'!H7),Final!H6<Final!H5,Final!H6<Final!H4,Final!H6<Final!H7),AND(ISBLANK(Final!H5),NOT(ISBLANK(Final!H7)),ISNUMBER(Final!H5:'Final'!H7),Final!H6>Final!H5,Final!H6<Final!H7,Final!H6<Final!H4)),"Y","."),IF(OR(AND(Final!H6>Final!H5,Final!H6>Final!H7),AND(Final!H6<Final!H5,Final!H6<Final!H7)),IF(AND(Final!$A6=Final!$A5,Final!$A6=Final!$A7),IF(Final!H6=MAX((Final!$A$2:'Final'!$A$100000=Final!$A5),Final!H5:INDEX(Final!H5:'Final'!H100003,SUMPRODUCT(--EXACT(Final!$A6,Final!$A5:'Final'!$A$100000)))),".","Y"),"."),"."))) -> . | ... J6: =IF(ISBLANK(Final!J6),"Y",IF(ISNUMBER(Final!$A5:'Final'!$A7),IF(OR(AND(NOT(ISBLANK(Final!J5)),NOT(ISBLANK(Final!J7)),ISNUMBER(Final!J5:'Final'!J7),Final!J6>Final!J5,Final!J6>Final!J7,Final!J6>Final!J8),AND(NOT(ISBLANK(Final!J5)),NOT(ISBLANK(Final!J7)),NOT(ISBLANK(Final!J8)),ISNUMBER(Final!J5:'Final'!J7),Final!J6<Final!J5,Final!J6>Final!J7,Final!J6<Final!J8),AND(NOT(ISBLANK(Final!J5)),NOT(ISBLANK(Final!J7)),ISNUMBER(Final!J5:'Final'!J7),Final!J6<Final!J5,Final!J6<Final!J4,Final!J6<Final!J7),AND(ISBLANK(Final!J5),NOT(ISBLANK(Final!J7)),ISNUMBER(Final!J5:'Final'!J7),Final!J6>Final!J5,Final!J6<Final!J7,Final!J6<Final!J4)),"Y","."),IF(OR(AND(Final!J6>Final!J5,Final!J6>Final!J7),AND(Final!J6<Final!J5,Final!J6<Final!J7)),IF(AND(Final!$A6=Final!$A5,Final!$A6=Final!$A7),IF(Final!J6=MAX((Final!$A$2:'Final'!$A$100000=Final!$A5),Final!J5:INDEX(Final!J5:'Final'!J100003,SUMPRODUCT(--EXACT(Final!$A6,Final!$A5:'Final'!$A$100000)))),".","Y"),"."),"."))) -> Y
A7: =IF(ISBLANK(Final!A7),"Y",IF(ISNUMBER(Final!$A6:'Final'!$A8),IF(OR(AND(NOT(ISBLANK(Final!A6)),NOT(ISBLANK(Final!A8)),ISNUMBER(Final!A6:'Final'!A8),Final!A7>Final!A6,Final!A7>Final!A8,Final!A7>Final!A9),AND(NOT(ISBLANK(Final!A6)),NOT(ISBLANK(Final!A8)),NOT(ISBLANK(Final!A9)),ISNUMBER(Final!A6:'Final'!A8),Final!A7<Final!A6,Final!A7>Final!A8,Final!A7<Final!A9),AND(NOT(ISBLANK(Final!A6)),NOT(ISBLANK(Final!A8)),ISNUMBER(Final!A6:'Final'!A8),Final!A7<Final!A6,Final!A7<Final!A5,Final!A7<Final!A8),AND(ISBLANK(Final!A6),NOT(ISBLANK(Final!A8)),ISNUMBER(Final!A6:'Final'!A8),Final!A7>Final!A6,Final!A7<Final!A8,Final!A7<Final!A5)),"Y","."),IF(OR(AND(Final!A7>Final!A6,Final!A7>Final!A8),AND(Final!A7<Final!A6,Final!A7<Final!A8)),IF(AND(Final!$A7=Final!$A6,Final!$A7=Final!$A8),IF(Final!A7=MAX((Final!$A$2:'Final'!$A$100000=Final!$A6),Final!A6:INDEX(Final!A6:'Final'!A100004,SUMPRODUCT(--EXACT(Final!$A7,Final!$A6:'Final'!$A$100000)))),".","Y"),"."),"."))) -> . | B7: =IF(ISBLANK(Final!B7),"Y",IF(ISNUMBER(Final!$A6:'Final'!$A8),IF(OR(AND(NOT(ISBLANK(Final!B6)),NOT(ISBLANK(Final!B8)),ISNUMBER(Final!B6:'Final'!B8),Final!B7>Final!B6,Final!B7>Final!B8,Final!B7>Final!B9),AND(NOT(ISBLANK(Final!B6)),NOT(ISBLANK(Final!B8)),NOT(ISBLANK(Final!B9)),ISNUMBER(Final!B6:'Final'!B8),Final!B7<Final!B6,Final!B7>Final!B8,Final!B7<Final!B9),AND(NOT(ISBLANK(Final!B6)),NOT(ISBLANK(Final!B8)),ISNUMBER(Final!B6:'Final'!B8),Final!B7<Final!B6,Final!B7<Final!B5,Final!B7<Final!B8),AND(ISBLANK(Final!B6),NOT(ISBLANK(Final!B8)),ISNUMBER(Final!B6:'Final'!B8),Final!B7>Final!B6,Final!B7<Final!B8,Final!B7<Final!B5)),"Y","."),IF(OR(AND(Final!B7>Final!B6,Final!B7>Final!B8),AND(Final!B7<Final!B6,Final!B7<Final!B8)),IF(AND(Final!$A7=Final!$A6,Final!$A7=Final!$A8),IF(Final!B7=MAX((Final!$A$2:'Final'!$A$100000=Final!$A6),Final!B6:INDEX(Final!B6:'Final'!B100004,SUMPRODUCT(--EXACT(Final!$A7,Final!$A6:'Final'!$A$100000)))),".","Y"),"."),"."))) -> . | C7: =IF(ISBLANK(Final!C7),"Y",IF(ISNUMBER(Final!$A6:'Final'!$A8),IF(OR(AND(NOT(ISBLANK(Final!C6)),NOT(ISBLANK(Final!C8)),ISNUMBER(Final!C6:'Final'!C8),Final!C7>Final!C6,Final!C7>Final!C8,Final!C7>Final!C9),AND(NOT(ISBLANK(Final!C6)),NOT(ISBLANK(Final!C8)),NOT(ISBLANK(Final!C9)),ISNUMBER(Final!C6:'Final'!C8),Final!C7<Final!C6,Final!C7>Final!C8,Final!C7<Final!C9),AND(NOT(ISBLANK(Final!C6)),NOT(ISBLANK(Final!C8)),ISNUMBER(Final!C6:'Final'!C8),Final!C7<Final!C6,Final!C7<Final!C5,Final!C7<Final!C8),AND(ISBLANK(Final!C6),NOT(ISBLANK(Final!C8)),ISNUMBER(Final!C6:'Final'!C8),Final!C7>Final!C6,Final!C7<Final!C8,Final!C7<Final!C5)),"Y","."),IF(OR(AND(Final!C7>Final!C6,Final!C7>Final!C8),AND(Final!C7<Final!C6,Final!C7<Final!C8)),IF(AND(Final!$A7=Final!$A6,Final!$A7=Final!$A8),IF(Final!C7=MAX((Final!$A$2:'Final'!$A$100000=Final!$A6),Final!C6:INDEX(Final!C6:'Final'!C100004,SUMPRODUCT(--EXACT(Final!$A7,Final!$A6:'Final'!$A$100000)))),".","Y"),"."),"."))) -> . | D7: =IF(ISBLANK(Final!D7),"Y",IF(ISNUMBER(Final!$A6:'Final'!$A8),IF(OR(AND(NOT(ISBLANK(Final!D6)),NOT(ISBLANK(Final!D8)),ISNUMBER(Final!D6:'Final'!D8),Final!D7>Final!D6,Final!D7>Final!D8,Final!D7>Final!D9),AND(NOT(ISBLANK(Final!D6)),NOT(ISBLANK(Final!D8)),NOT(ISBLANK(Final!D9)),ISNUMBER(Final!D6:'Final'!D8),Final!D7<Final!D6,Final!D7>Final!D8,Final!D7<Final!D9),AND(NOT(ISBLANK(Final!D6)),NOT(ISBLANK(Final!D8)),ISNUMBER(Final!D6:'Final'!D8),Final!D7<Final!D6,Final!D7<Final!D5,Final!D7<Final!D8),AND(ISBLANK(Final!D6),NOT(ISBLANK(Final!D8)),ISNUMBER(Final!D6:'Final'!D8),Final!D7>Final!D6,Final!D7<Final!D8,Final!D7<Final!D5)),"Y","."),IF(OR(AND(Final!D7>Final!D6,Final!D7>Final!D8),AND(Final!D7<Final!D6,Final!D7<Final!D8)),IF(AND(Final!$A7=Final!$A6,Final!$A7=Final!$A8),IF(Final!D7=MAX((Final!$A$2:'Final'!$A$100000=Final!$A6),Final!D6:INDEX(Final!D6:'Final'!D100004,SUMPRODUCT(--EXACT(Final!$A7,Final!$A6:'Final'!$A$100000)))),".","Y"),"."),"."))) -> . | E7: =IF(ISBLANK(Final!E7),"Y",IF(ISNUMBER(Final!$A6:'Final'!$A8),IF(OR(AND(NOT(ISBLANK(Final!E6)),NOT(ISBLANK(Final!E8)),ISNUMBER(Final!E6:'Final'!E8),Final!E7>Final!E6,Final!E7>Final!E8,Final!E7>Final!E9),AND(NOT(ISBLANK(Final!E6)),NOT(ISBLANK(Final!E8)),NOT(ISBLANK(Final!E9)),ISNUMBER(Final!E6:'Final'!E8),Final!E7<Final!E6,Final!E7>Final!E8,Final!E7<Final!E9),AND(NOT(ISBLANK(Final!E6)),NOT(ISBLANK(Final!E8)),ISNUMBER(Final!E6:'Final'!E8),Final!E7<Final!E6,Final!E7<Final!E5,Final!E7<Final!E8),AND(ISBLANK(Final!E6),NOT(ISBLANK(Final!E8)),ISNUMBER(Final!E6:'Final'!E8),Final!E7>Final!E6,Final!E7<Final!E8,Final!E7<Final!E5)),"Y","."),IF(OR(AND(Final!E7>Final!E6,Final!E7>Final!E8),AND(Final!E7<Final!E6,Final!E7<Final!E8)),IF(AND(Final!$A7=Final!$A6,Final!$A7=Final!$A8),IF(Final!E7=MAX((Final!$A$2:'Final'!$A$100000=Final!$A6),Final!E6:INDEX(Final!E6:'Final'!E100004,SUMPRODUCT(--EXACT(Final!$A7,Final!$A6:'Final'!$A$100000)))),".","Y"),"."),"."))) -> . | F7: =IF(ISBLANK(Final!F7),"Y",IF(ISNUMBER(Final!$A6:'Final'!$A8),IF(OR(AND(NOT(ISBLANK(Final!F6)),NOT(ISBLANK(Final!F8)),ISNUMBER(Final!F6:'Final'!F8),Final!F7>Final!F6,Final!F7>Final!F8,Final!F7>Final!F9),AND(NOT(ISBLANK(Final!F6)),NOT(ISBLANK(Final!F8)),NOT(ISBLANK(Final!F9)),ISNUMBER(Final!F6:'Final'!F8),Final!F7<Final!F6,Final!F7>Final!F8,Final!F7<Final!F9),AND(NOT(ISBLANK(Final!F6)),NOT(ISBLANK(Final!F8)),ISNUMBER(Final!F6:'Final'!F8),Final!F7<Final!F6,Final!F7<Final!F5,Final!F7<Final!F8),AND(ISBLANK(Final!F6),NOT(ISBLANK(Final!F8)),ISNUMBER(Final!F6:'Final'!F8),Final!F7>Final!F6,Final!F7<Final!F8,Final!F7<Final!F5)),"Y","."),IF(OR(AND(Final!F7>Final!F6,Final!F7>Final!F8),AND(Final!F7<Final!F6,Final!F7<Final!F8)),IF(AND(Final!$A7=Final!$A6,Final!$A7=Final!$A8),IF(Final!F7=MAX((Final!$A$2:'Final'!$A$100000=Final!$A6),Final!F6:INDEX(Final!F6:'Final'!F100004,SUMPRODUCT(--EXACT(Final!$A7,Final!$A6:'Final'!$A$100000)))),".","Y"),"."),"."))) -> . | G7: =IF(ISBLANK(Final!G7),"Y",IF(ISNUMBER(Final!$A6:'Final'!$A8),IF(OR(AND(NOT(ISBLANK(Final!G6)),NOT(ISBLANK(Final!G8)),ISNUMBER(Final!G6:'Final'!G8),Final!G7>Final!G6,Final!G7>Final!G8,Final!G7>Final!G9),AND(NOT(ISBLANK(Final!G6)),NOT(ISBLANK(Final!G8)),NOT(ISBLANK(Final!G9)),ISNUMBER(Final!G6:'Final'!G8),Final!G7<Final!G6,Final!G7>Final!G8,Final!G7<Final!G9),AND(NOT(ISBLANK(Final!G6)),NOT(ISBLANK(Final!G8)),ISNUMBER(Final!G6:'Final'!G8),Final!G7<Final!G6,Final!G7<Final!G5,Final!G7<Final!G8),AND(ISBLANK(Final!G6),NOT(ISBLANK(Final!G8)),ISNUMBER(Final!G6:'Final'!G8),Final!G7>Final!G6,Final!G7<Final!G8,Final!G7<Final!G5)),"Y","."),IF(OR(AND(Final!G7>Final!G6,Final!G7>Final!G8),AND(Final!G7<Final!G6,Final!G7<Final!G8)),IF(AND(Final!$A7=Final!$A6,Final!$A7=Final!$A8),IF(Final!G7=MAX((Final!$A$2:'Final'!$A$100000=Final!$A6),Final!G6:INDEX(Final!G6:'Final'!G100004,SUMPRODUCT(--EXACT(Final!$A7,Final!$A6:'Final'!$A$100000)))),".","Y"),"."),"."))) -> . | H7: =IF(ISBLANK(Final!H7),"Y",IF(ISNUMBER(Final!$A6:'Final'!$A8),IF(OR(AND(NOT(ISBLANK(Final!H6)),NOT(ISBLANK(Final!H8)),ISNUMBER(Final!H6:'Final'!H8),Final!H7>Final!H6,Final!H7>Final!H8,Final!H7>Final!H9),AND(NOT(ISBLANK(Final!H6)),NOT(ISBLANK(Final!H8)),NOT(ISBLANK(Final!H9)),ISNUMBER(Final!H6:'Final'!H8),Final!H7<Final!H6,Final!H7>Final!H8,Final!H7<Final!H9),AND(NOT(ISBLANK(Final!H6)),NOT(ISBLANK(Final!H8)),ISNUMBER(Final!H6:'Final'!H8),Final!H7<Final!H6,Final!H7<Final!H5,Final!H7<Final!H8),AND(ISBLANK(Final!H6),NOT(ISBLANK(Final!H8)),ISNUMBER(Final!H6:'Final'!H8),Final!H7>Final!H6,Final!H7<Final!H8,Final!H7<Final!H5)),"Y","."),IF(OR(AND(Final!H7>Final!H6,Final!H7>Final!H8),AND(Final!H7<Final!H6,Final!H7<Final!H8)),IF(AND(Final!$A7=Final!$A6,Final!$A7=Final!$A8),IF(Final!H7=MAX((Final!$A$2:'Final'!$A$100000=Final!$A6),Final!H6:INDEX(Final!H6:'Final'!H100004,SUMPRODUCT(--EXACT(Final!$A7,Final!$A6:'Final'!$A$100000)))),".","Y"),"."),"."))) -> . | ... J7: =IF(ISBLANK(Final!J7),"Y",IF(ISNUMBER(Final!$A6:'Final'!$A8),IF(OR(AND(NOT(ISBLANK(Final!J6)),NOT(ISBLANK(Final!J8)),ISNUMBER(Final!J6:'Final'!J8),Final!J7>Final!J6,Final!J7>Final!J8,Final!J7>Final!J9),AND(NOT(ISBLANK(Final!J6)),NOT(ISBLANK(Final!J8)),NOT(ISBLANK(Final!J9)),ISNUMBER(Final!J6:'Final'!J8),Final!J7<Final!J6,Final!J7>Final!J8,Final!J7<Final!J9),AND(NOT(ISBLANK(Final!J6)),NOT(ISBLANK(Final!J8)),ISNUMBER(Final!J6:'Final'!J8),Final!J7<Final!J6,Final!J7<Final!J5,Final!J7<Final!J8),AND(ISBLANK(Final!J6),NOT(ISBLANK(Final!J8)),ISNUMBER(Final!J6:'Final'!J8),Final!J7>Final!J6,Final!J7<Final!J8,Final!J7<Final!J5)),"Y","."),IF(OR(AND(Final!J7>Final!J6,Final!J7>Final!J8),AND(Final!J7<Final!J6,Final!J7<Final!J8)),IF(AND(Final!$A7=Final!$A6,Final!$A7=Final!$A8),IF(Final!J7=MAX((Final!$A$2:'Final'!$A$100000=Final!$A6),Final!J6:INDEX(Final!J6:'Final'!J100004,SUMPRODUCT(--EXACT(Final!$A7,Final!$A6:'Final'!$A$100000)))),".","Y"),"."),"."))) -> Y
A8: =IF(ISBLANK(Final!A8),"Y",IF(ISNUMBER(Final!$A7:'Final'!$A9),IF(OR(AND(NOT(ISBLANK(Final!A7)),NOT(ISBLANK(Final!A9)),ISNUMBER(Final!A7:'Final'!A9),Final!A8>Final!A7,Final!A8>Final!A9,Final!A8>Final!A10),AND(NOT(ISBLANK(Final!A7)),NOT(ISBLANK(Final!A9)),NOT(ISBLANK(Final!A10)),ISNUMBER(Final!A7:'Final'!A9),Final!A8<Final!A7,Final!A8>Final!A9,Final!A8<Final!A10),AND(NOT(ISBLANK(Final!A7)),NOT(ISBLANK(Final!A9)),ISNUMBER(Final!A7:'Final'!A9),Final!A8<Final!A7,Final!A8<Final!A6,Final!A8<Final!A9),AND(ISBLANK(Final!A7),NOT(ISBLANK(Final!A9)),ISNUMBER(Final!A7:'Final'!A9),Final!A8>Final!A7,Final!A8<Final!A9,Final!A8<Final!A6)),"Y","."),IF(OR(AND(Final!A8>Final!A7,Final!A8>Final!A9),AND(Final!A8<Final!A7,Final!A8<Final!A9)),IF(AND(Final!$A8=Final!$A7,Final!$A8=Final!$A9),IF(Final!A8=MAX((Final!$A$2:'Final'!$A$100000=Final!$A7),Final!A7:INDEX(Final!A7:'Final'!A100005,SUMPRODUCT(--EXACT(Final!$A8,Final!$A7:'Final'!$A$100000)))),".","Y"),"."),"."))) -> . | B8: =IF(ISBLANK(Final!B8),"Y",IF(ISNUMBER(Final!$A7:'Final'!$A9),IF(OR(AND(NOT(ISBLANK(Final!B7)),NOT(ISBLANK(Final!B9)),ISNUMBER(Final!B7:'Final'!B9),Final!B8>Final!B7,Final!B8>Final!B9,Final!B8>Final!B10),AND(NOT(ISBLANK(Final!B7)),NOT(ISBLANK(Final!B9)),NOT(ISBLANK(Final!B10)),ISNUMBER(Final!B7:'Final'!B9),Final!B8<Final!B7,Final!B8>Final!B9,Final!B8<Final!B10),AND(NOT(ISBLANK(Final!B7)),NOT(ISBLANK(Final!B9)),ISNUMBER(Final!B7:'Final'!B9),Final!B8<Final!B7,Final!B8<Final!B6,Final!B8<Final!B9),AND(ISBLANK(Final!B7),NOT(ISBLANK(Final!B9)),ISNUMBER(Final!B7:'Final'!B9),Final!B8>Final!B7,Final!B8<Final!B9,Final!B8<Final!B6)),"Y","."),IF(OR(AND(Final!B8>Final!B7,Final!B8>Final!B9),AND(Final!B8<Final!B7,Final!B8<Final!B9)),IF(AND(Final!$A8=Final!$A7,Final!$A8=Final!$A9),IF(Final!B8=MAX((Final!$A$2:'Final'!$A$100000=Final!$A7),Final!B7:INDEX(Final!B7:'Final'!B100005,SUMPRODUCT(--EXACT(Final!$A8,Final!$A7:'Final'!$A$100000)))),".","Y"),"."),"."))) -> . | C8: =IF(ISBLANK(Final!C8),"Y",IF(ISNUMBER(Final!$A7:'Final'!$A9),IF(OR(AND(NOT(ISBLANK(Final!C7)),NOT(ISBLANK(Final!C9)),ISNUMBER(Final!C7:'Final'!C9),Final!C8>Final!C7,Final!C8>Final!C9,Final!C8>Final!C10),AND(NOT(ISBLANK(Final!C7)),NOT(ISBLANK(Final!C9)),NOT(ISBLANK(Final!C10)),ISNUMBER(Final!C7:'Final'!C9),Final!C8<Final!C7,Final!C8>Final!C9,Final!C8<Final!C10),AND(NOT(ISBLANK(Final!C7)),NOT(ISBLANK(Final!C9)),ISNUMBER(Final!C7:'Final'!C9),Final!C8<Final!C7,Final!C8<Final!C6,Final!C8<Final!C9),AND(ISBLANK(Final!C7),NOT(ISBLANK(Final!C9)),ISNUMBER(Final!C7:'Final'!C9),Final!C8>Final!C7,Final!C8<Final!C9,Final!C8<Final!C6)),"Y","."),IF(OR(AND(Final!C8>Final!C7,Final!C8>Final!C9),AND(Final!C8<Final!C7,Final!C8<Final!C9)),IF(AND(Final!$A8=Final!$A7,Final!$A8=Final!$A9),IF(Final!C8=MAX((Final!$A$2:'Final'!$A$100000=Final!$A7),Final!C7:INDEX(Final!C7:'Final'!C100005,SUMPRODUCT(--EXACT(Final!$A8,Final!$A7:'Final'!$A$100000)))),".","Y"),"."),"."))) -> . | D8: =IF(ISBLANK(Final!D8),"Y",IF(ISNUMBER(Final!$A7:'Final'!$A9),IF(OR(AND(NOT(ISBLANK(Final!D7)),NOT(ISBLANK(Final!D9)),ISNUMBER(Final!D7:'Final'!D9),Final!D8>Final!D7,Final!D8>Final!D9,Final!D8>Final!D10),AND(NOT(ISBLANK(Final!D7)),NOT(ISBLANK(Final!D9)),NOT(ISBLANK(Final!D10)),ISNUMBER(Final!D7:'Final'!D9),Final!D8<Final!D7,Final!D8>Final!D9,Final!D8<Final!D10),AND(NOT(ISBLANK(Final!D7)),NOT(ISBLANK(Final!D9)),ISNUMBER(Final!D7:'Final'!D9),Final!D8<Final!D7,Final!D8<Final!D6,Final!D8<Final!D9),AND(ISBLANK(Final!D7),NOT(ISBLANK(Final!D9)),ISNUMBER(Final!D7:'Final'!D9),Final!D8>Final!D7,Final!D8<Final!D9,Final!D8<Final!D6)),"Y","."),IF(OR(AND(Final!D8>Final!D7,Final!D8>Final!D9),AND(Final!D8<Final!D7,Final!D8<Final!D9)),IF(AND(Final!$A8=Final!$A7,Final!$A8=Final!$A9),IF(Final!D8=MAX((Final!$A$2:'Final'!$A$100000=Final!$A7),Final!D7:INDEX(Final!D7:'Final'!D100005,SUMPRODUCT(--EXACT(Final!$A8,Final!$A7:'Final'!$A$100000)))),".","Y"),"."),"."))) -> . | E8: =IF(ISBLANK(Final!E8),"Y",IF(ISNUMBER(Final!$A7:'Final'!$A9),IF(OR(AND(NOT(ISBLANK(Final!E7)),NOT(ISBLANK(Final!E9)),ISNUMBER(Final!E7:'Final'!E9),Final!E8>Final!E7,Final!E8>Final!E9,Final!E8>Final!E10),AND(NOT(ISBLANK(Final!E7)),NOT(ISBLANK(Final!E9)),NOT(ISBLANK(Final!E10)),ISNUMBER(Final!E7:'Final'!E9),Final!E8<Final!E7,Final!E8>Final!E9,Final!E8<Final!E10),AND(NOT(ISBLANK(Final!E7)),NOT(ISBLANK(Final!E9)),ISNUMBER(Final!E7:'Final'!E9),Final!E8<Final!E7,Final!E8<Final!E6,Final!E8<Final!E9),AND(ISBLANK(Final!E7),NOT(ISBLANK(Final!E9)),ISNUMBER(Final!E7:'Final'!E9),Final!E8>Final!E7,Final!E8<Final!E9,Final!E8<Final!E6)),"Y","."),IF(OR(AND(Final!E8>Final!E7,Final!E8>Final!E9),AND(Final!E8<Final!E7,Final!E8<Final!E9)),IF(AND(Final!$A8=Final!$A7,Final!$A8=Final!$A9),IF(Final!E8=MAX((Final!$A$2:'Final'!$A$100000=Final!$A7),Final!E7:INDEX(Final!E7:'Final'!E100005,SUMPRODUCT(--EXACT(Final!$A8,Final!$A7:'Final'!$A$100000)))),".","Y"),"."),"."))) -> . | F8: =IF(ISBLANK(Final!F8),"Y",IF(ISNUMBER(Final!$A7:'Final'!$A9),IF(OR(AND(NOT(ISBLANK(Final!F7)),NOT(ISBLANK(Final!F9)),ISNUMBER(Final!F7:'Final'!F9),Final!F8>Final!F7,Final!F8>Final!F9,Final!F8>Final!F10),AND(NOT(ISBLANK(Final!F7)),NOT(ISBLANK(Final!F9)),NOT(ISBLANK(Final!F10)),ISNUMBER(Final!F7:'Final'!F9),Final!F8<Final!F7,Final!F8>Final!F9,Final!F8<Final!F10),AND(NOT(ISBLANK(Final!F7)),NOT(ISBLANK(Final!F9)),ISNUMBER(Final!F7:'Final'!F9),Final!F8<Final!F7,Final!F8<Final!F6,Final!F8<Final!F9),AND(ISBLANK(Final!F7),NOT(ISBLANK(Final!F9)),ISNUMBER(Final!F7:'Final'!F9),Final!F8>Final!F7,Final!F8<Final!F9,Final!F8<Final!F6)),"Y","."),IF(OR(AND(Final!F8>Final!F7,Final!F8>Final!F9),AND(Final!F8<Final!F7,Final!F8<Final!F9)),IF(AND(Final!$A8=Final!$A7,Final!$A8=Final!$A9),IF(Final!F8=MAX((Final!$A$2:'Final'!$A$100000=Final!$A7),Final!F7:INDEX(Final!F7:'Final'!F100005,SUMPRODUCT(--EXACT(Final!$A8,Final!$A7:'Final'!$A$100000)))),".","Y"),"."),"."))) -> . | G8: =IF(ISBLANK(Final!G8),"Y",IF(ISNUMBER(Final!$A7:'Final'!$A9),IF(OR(AND(NOT(ISBLANK(Final!G7)),NOT(ISBLANK(Final!G9)),ISNUMBER(Final!G7:'Final'!G9),Final!G8>Final!G7,Final!G8>Final!G9,Final!G8>Final!G10),AND(NOT(ISBLANK(Final!G7)),NOT(ISBLANK(Final!G9)),NOT(ISBLANK(Final!G10)),ISNUMBER(Final!G7:'Final'!G9),Final!G8<Final!G7,Final!G8>Final!G9,Final!G8<Final!G10),AND(NOT(ISBLANK(Final!G7)),NOT(ISBLANK(Final!G9)),ISNUMBER(Final!G7:'Final'!G9),Final!G8<Final!G7,Final!G8<Final!G6,Final!G8<Final!G9),AND(ISBLANK(Final!G7),NOT(ISBLANK(Final!G9)),ISNUMBER(Final!G7:'Final'!G9),Final!G8>Final!G7,Final!G8<Final!G9,Final!G8<Final!G6)),"Y","."),IF(OR(AND(Final!G8>Final!G7,Final!G8>Final!G9),AND(Final!G8<Final!G7,Final!G8<Final!G9)),IF(AND(Final!$A8=Final!$A7,Final!$A8=Final!$A9),IF(Final!G8=MAX((Final!$A$2:'Final'!$A$100000=Final!$A7),Final!G7:INDEX(Final!G7:'Final'!G100005,SUMPRODUCT(--EXACT(Final!$A8,Final!$A7:'Final'!$A$100000)))),".","Y"),"."),"."))) -> . | H8: =IF(ISBLANK(Final!H8),"Y",IF(ISNUMBER(Final!$A7:'Final'!$A9),IF(OR(AND(NOT(ISBLANK(Final!H7)),NOT(ISBLANK(Final!H9)),ISNUMBER(Final!H7:'Final'!H9),Final!H8>Final!H7,Final!H8>Final!H9,Final!H8>Final!H10),AND(NOT(ISBLANK(Final!H7)),NOT(ISBLANK(Final!H9)),NOT(ISBLANK(Final!H10)),ISNUMBER(Final!H7:'Final'!H9),Final!H8<Final!H7,Final!H8>Final!H9,Final!H8<Final!H10),AND(NOT(ISBLANK(Final!H7)),NOT(ISBLANK(Final!H9)),ISNUMBER(Final!H7:'Final'!H9),Final!H8<Final!H7,Final!H8<Final!H6,Final!H8<Final!H9),AND(ISBLANK(Final!H7),NOT(ISBLANK(Final!H9)),ISNUMBER(Final!H7:'Final'!H9),Final!H8>Final!H7,Final!H8<Final!H9,Final!H8<Final!H6)),"Y","."),IF(OR(AND(Final!H8>Final!H7,Final!H8>Final!H9),AND(Final!H8<Final!H7,Final!H8<Final!H9)),IF(AND(Final!$A8=Final!$A7,Final!$A8=Final!$A9),IF(Final!H8=MAX((Final!$A$2:'Final'!$A$100000=Final!$A7),Final!H7:INDEX(Final!H7:'Final'!H100005,SUMPRODUCT(--EXACT(Final!$A8,Final!$A7:'Final'!$A$100000)))),".","Y"),"."),"."))) -> . | ... J8: =IF(ISBLANK(Final!J8),"Y",IF(ISNUMBER(Final!$A7:'Final'!$A9),IF(OR(AND(NOT(ISBLANK(Final!J7)),NOT(ISBLANK(Final!J9)),ISNUMBER(Final!J7:'Final'!J9),Final!J8>Final!J7,Final!J8>Final!J9,Final!J8>Final!J10),AND(NOT(ISBLANK(Final!J7)),NOT(ISBLANK(Final!J9)),NOT(ISBLANK(Final!J10)),ISNUMBER(Final!J7:'Final'!J9),Final!J8<Final!J7,Final!J8>Final!J9,Final!J8<Final!J10),AND(NOT(ISBLANK(Final!J7)),NOT(ISBLANK(Final!J9)),ISNUMBER(Final!J7:'Final'!J9),Final!J8<Final!J7,Final!J8<Final!J6,Final!J8<Final!J9),AND(ISBLANK(Final!J7),NOT(ISBLANK(Final!J9)),ISNUMBER(Final!J7:'Final'!J9),Final!J8>Final!J7,Final!J8<Final!J9,Final!J8<Final!J6)),"Y","."),IF(OR(AND(Final!J8>Final!J7,Final!J8>Final!J9),AND(Final!J8<Final!J7,Final!J8<Final!J9)),IF(AND(Final!$A8=Final!$A7,Final!$A8=Final!$A9),IF(Final!J8=MAX((Final!$A$2:'Final'!$A$100000=Final!$A7),Final!J7:INDEX(Final!J7:'Final'!J100005,SUMPRODUCT(--EXACT(Final!$A8,Final!$A7:'Final'!$A$100000)))),".","Y"),"."),"."))) -> .
